Workbook

Sheet Terms
A1: ID | B1: Term | C1: Also Known As | D1: Category | E1: Applies To Lines | F1: Plain-English Definition | G1: Example | H1: Where You'll See It | I1: Most Relevant For | J1: Difficulty | K1: Usage Frequency | L1: Related Terms | M1: US Notes
A2: section-1035-exchange | B2: 1035 Exchange | D2: Line-Specific | E2: Life | F2: A tax-free swap of one life insurance or annuity policy for another under IRS Section 1035. | G2: You exchange an old annuity for a new one without paying tax. | H2: Application form | I2: Individuals, Underwriters, Product Owners | J2: Advanced | K2: Low | L2: replacement
A3: seven-pay-test | B3: 7-Pay Test | D3: Line-Specific | E3: Life | F3: A federal tax test that checks whether premiums in the first seven years exceed limits, which would make a policy a MEC. | G3: Premiums above the 7-pay limit trigger MEC status. | H3: Policy administration system | I3: Developers, Underwriters | J3: Advanced | K3: Low | L3: modified-endowment-contract
A4: a-plus-report | B4: A-PLUS Report | C4: Automated Property Loss Underwriting System | D4: Underwriting | E4: Property, Motor | F4: A Verisk database report of past property and auto claims, similar to CLUE. | G4: An underwriter checks A-PLUS for prior losses. | H4: Underwriting system | I4: Developers, Underwriters | J4: Advanced | K4: Low | L4: clue-report, loss-history
A5: aais | B5: AAIS | C5: American Association of Insurance Services | D5: Technology | E5: Property, Commercial, Marine/Aviation/Transit, Agriculture | F5: An advisory organization, owned by member insurers, that provides standard forms and loss costs, similar to ISO. | G5: A mutual insurer uses AAIS farm forms. | H5: Policy document | I5: Underwriters, Product Owners | J5: Advanced | K5: Low | L5: iso
A6: ab-initio | B6: Ab Initio | D6: Legal/Latin | E6: All | F6: Latin for 'from the beginning'. A policy void ab initio is treated as if it never existed. | G6: A policy obtained by fraud is rescinded ab initio and the premium refunded. | H6: Policy document | I6: Developers, Underwriters | J6: Advanced | K6: Low | L6: rescission, void-policy
A7: abandonment | B7: Abandonment | D7: Claims | E7: Marine/Aviation/Transit | F7: Giving up ownership of damaged property to the insurer in exchange for a total loss payment. | G7: A shipowner abandons a wrecked vessel to the insurers. | H7: Policy document | I7: Underwriters | J7: Advanced | K7: Low | L7: constructive-total-loss, salvage | M7: Property policies usually say the insured cannot abandon property to the insurer.
A8: accelerated-death-benefit-rider | B8: Accelerated Death Benefit Rider | C8: Living Benefits Rider | D8: Line-Specific | E8: Life | F8: A rider that lets you receive part of the death benefit early if you are terminally, chronically or critically ill. | G8: You receive 50% of the benefit after a terminal diagnosis. | H8: Policy document | I8: Individuals, Underwriters, Product Owners | J8: Intermediate | K8: Medium | L8: rider, chronic-illness-rider
A9: accelerated-underwriting | B9: Accelerated Underwriting | D9: Underwriting | E9: Life | F9: Using data and algorithms to approve some life applicants without a medical exam. | G9: A healthy 30-year-old is approved in minutes without blood tests. | H9: Underwriting system | I9: Developers, Underwriters, Product Owners | J9: Intermediate | K9: Medium | L9: medical-underwriting, paramedical-exam, predictive-model
A10: accident | B10: Accident | D10: Policy Wording | E10: All | F10: A sudden, unexpected and unintended event that causes injury or damage. | G10: Slipping on ice and breaking an arm is an accident. | H10: Policy document | I10: Individuals, Underwriters | J10: Beginner | K10: High | L10: occurrence, accidental-death-and-dismemberment
A11: accident-forgiveness | B11: Accident Forgiveness | D11: Underwriting | E11: Motor | F11: A feature where your first at-fault accident doesn't raise your premium. | G11: No surcharge after your first fender-bender. | H11: Policy document | I11: Individuals, Product Owners | J11: Beginner | K11: Low | L11: driving-record-points | M11: Banned in some states such as California.
A12: accident-insurance | B12: Accident Insurance | D12: Line-Specific | E12: Health | F12: Insurance paying set amounts for injuries from accidents, such as fractures or ER visits. | G12: $500 for a broken arm. | H12: Policy document | I12: Individuals, Product Owners | J12: Beginner | K12: Medium | L12: accidental-death-and-dismemberment, critical-illness-insurance
A13: accident-year | B13: Accident Year | C13: AY | D13: Finance & Actuarial | E13: Property, Casualty/Liability, Motor, Commercial | F13: Grouping of losses by the year the accident happened. | G13: All losses from accidents in 2024 belong to AY 2024. | H13: Financial statements | I13: Developers, Product Owners | J13: Advanced | K13: Medium | L13: policy-year, calendar-year, underwriting-year
A14: accidental-death-and-dismemberment | B14: Accidental Death and Dismemberment | C14: AD&D | D14: Line-Specific | E14: Life, Health | F14: Insurance paying if you die or lose a limb, eyesight or hearing in an accident. | G14: AD&D pays 50% of the benefit for loss of one hand. | H14: Policy document | I14: Individuals, Developers, Product Owners | J14: Intermediate | K14: Medium | L14: accident-insurance, accidental-death-benefit-rider
A15: accidental-death-benefit-rider | B15: Accidental Death Benefit Rider | C15: ADB; Double Indemnity | D15: Line-Specific | E15: Life | F15: A rider that pays an extra benefit if death results from an accident. | G15: An extra $250,000 paid for accidental death. | H15: Policy document | I15: Individuals, Underwriters | J15: Intermediate | K15: Medium | L15: rider, accidental-death-and-dismemberment
A16: aggregation | B16: Accumulation | C16: Aggregation; Concentration Risk | D16: Underwriting | E16: Property, Commercial, Financial Lines, Reinsurance | F16: The build-up of many insured risks exposed to the same event. | G16: Too many insured homes in one coastal county. | H16: Underwriting system | I16: Underwriters, Product Owners | J16: Advanced | K16: Low | L16: catastrophe-model, probable-maximum-loss
A17: accumulation-phase | B17: Accumulation Phase | D17: Line-Specific | E17: Life | F17: The period when money in a deferred annuity grows before payouts start. | G17: Contributions grow tax-deferred in the accumulation phase. | H17: Policy document | I17: Individuals, Developers | J17: Intermediate | K17: Low | L17: deferred-annuity, annuitization
A18: acord | B18: ACORD | C18: Association for Cooperative Operations Research and Development | D18: Technology | E18: All | F18: A nonprofit that sets data standards (XML, JSON, forms) for exchanging insurance information. | G18: Agency software sends ACORD XML to a carrier. | H18: Data exchange/integration specs | I18: Developers, Product Owners | J18: Intermediate | K18: Medium | L18: acord-forms, acord-al3
A19: acord-al3 | B19: ACORD AL3 | D19: Technology | E19: All | F19: An older ACORD standard file format used to download policy data from carriers to agency systems. | G19: A carrier sends daily AL3 downloads to agents. | H19: Data exchange/integration specs | I19: Developers | J19: Advanced | K19: Low | L19: acord
A20: acord-forms | B20: ACORD Forms | D20: Technology | E20: All | F20: Standardized application and certificate forms used across the US industry, such as ACORD 25 (certificate of liability insurance) and ACORD 125. | G20: A broker fills out ACORD 125 and 126 for a commercial GL submission. | H20: Application form, Agent/broker communications | I20: Developers, Underwriters, Product Owners | J20: Intermediate | K20: Medium | L20: acord, certificate-of-insurance, application
A21: acquisition-costs | B21: Acquisition Costs | D21: Finance & Actuarial | E21: All | F21: Costs of getting new business, such as commissions, marketing and underwriting. | G21: Commissions and premium taxes are acquisition costs. | H21: Financial statements | I21: Developers, Product Owners | J21: Intermediate | K21: Medium | L21: expense-ratio, deferred-acquisition-costs, commission
A22: act-of-god | B22: Act of God | C22: Force of Nature | D22: Legal/Latin | E22: All | F22: A natural event outside human control, such as a flood, earthquake or lightning. | G22: Lightning striking a barn is an act of God. | H22: Policy document | I22: Individuals, Underwriters | J22: Beginner | K22: Medium | L22: force-majeure, peril, catastrophe
A23: activities-of-daily-living | B23: Activities of Daily Living | C23: ADLs | D23: Line-Specific | E23: Life, Health | F23: Basic self-care tasks, usually bathing, dressing, eating, toileting, continence and transferring, used to trigger long-term care benefits. | G23: Needing help with two ADLs qualifies you for LTC benefits. | H23: Policy document, Claim documents | I23: Individuals, Underwriters | J23: Intermediate | K23: Medium | L23: long-term-care-insurance, chronic-illness-rider
A24: actual-cash-value | B24: Actual Cash Value | C24: ACV | D24: Core Concept | E24: Property, Motor | F24: The value of property at the time of loss: replacement cost minus depreciation. | G24: A 5-year-old TV that costs $1,000 new may be worth $400 ACV. | H24: Policy document, Claim documents | I24: Individuals, Developers, Underwriters, Product Owners | J24: Beginner | K24: High | L24: replacement-cost, depreciation, indemnity | M24: Some states define ACV by statute or case law, including whether labor can be depreciated.
A25: actual-production-history | B25: Actual Production History | C25: APH | D25: Underwriting | E25: Agriculture | F25: A farmer's historical average yields, used to set crop insurance guarantees. | G25: A 10-year APH of 180 bushels per acre. | H25: Underwriting system | I25: Developers, Underwriters | J25: Advanced | K25: Low | L25: multi-peril-crop-insurance
A26: actuarial-value | B26: Actuarial Value | C26: AV | D26: Finance & Actuarial | E26: Health | F26: The percentage of total average costs for covered benefits that a plan pays. | G26: A silver plan has about 70% actuarial value. | H26: Product specification | I26: Developers, Product Owners | J26: Advanced | K26: Low | L26: metal-tiers
A27: actuary | B27: Actuary | D27: Finance & Actuarial | E27: All | F27: A professional who uses math and statistics to price insurance, set reserves and measure risk. | G27: An actuary calculates how much to charge 30-year-old non-smokers for term life. | I27: Developers, Underwriters, Product Owners | J27: Beginner | K27: Medium | L27: law-of-large-numbers, reserves | M27: Credentialed by the CAS (property/casualty) or SOA (life/health).
A28: additional-insured | B28: Additional Insured | C28: AI | D28: Policy Wording | E28: Property, Casualty/Liability, Commercial | F28: A person or company added to someone else's policy so they are also protected, often required by a contract. | G28: A landlord requires a tenant's liability policy to list the landlord as an additional insured. | H28: Policy document, Declarations page | I28: Developers, Underwriters, Product Owners | J28: Intermediate | K28: High | L28: named-insured, certificate-of-insurance, endorsement
A29: additional-living-expense | B29: Additional Living Expense | C29: ALE | D29: Policy Wording | E29: Property | F29: The increase in living costs, such as rent and meals, after a covered loss forces you out of your home. | G29: Paying $2,000/month rent while your home is rebuilt. | H29: Policy document | I29: Individuals, Underwriters | J29: Beginner | K29: Medium | L29: loss-of-use, fair-rental-value
A30: additional-premium | B30: Additional Premium | C30: AP | D30: Lifecycle | E30: All | F30: Extra premium charged because of a mid-term change that increases the risk. | G30: Adding a pool to your home policy costs $80 additional premium. | H30: Billing statement | I30: Developers, Underwriters | J30: Beginner | K30: Medium | L30: return-premium, mid-term-adjustment
A31: administrative-services-only | B31: Administrative Services Only | C31: ASO | D31: Distribution | E31: Health | F31: An arrangement where an insurer or TPA processes claims for a self-funded plan but doesn't take the risk. | G31: A big insurer handles claims for an employer's plan under an ASO contract. | I31: Developers, Product Owners | J31: Advanced | K31: Low | L31: self-funded-plan, third-party-administrator
A32: admitted-insurer | B32: Admitted Insurer | C32: Admitted Carrier; Licensed Insurer | D32: Regulation | E32: All | F32: An insurer licensed by a state to do business there, subject to its rate and form rules and covered by its guaranty fund. | G32: Most personal auto insurers are admitted. | H32: Regulatory filings | I32: Individuals, Developers, Underwriters, Product Owners | J32: Intermediate | K32: Medium | L32: non-admitted-insurer, guaranty-fund, surplus-lines
A33: adverse-action-notice | B33: Adverse Action Notice | D33: Regulation | E33: All | F33: A notice explaining that a consumer report influenced a decision to decline or charge more. | G33: A letter says your insurance score affected your premium. | H33: Regulatory filings | I33: Developers, Underwriters | J33: Intermediate | K33: Low | L33: fcra
A34: adverse-development-cover | B34: Adverse Development Cover | C34: ADC | D34: Reinsurance | E34: Reinsurance, Alternative Risk Transfer | F34: Reinsurance that pays if reserves for past claims turn out to be too low. | G34: Covers reserve growth above $500M on old liability claims. | H34: Reinsurance contract | I34: Product Owners | J34: Advanced | K34: Low | L34: portfolio-transfer, reserve-development
A35: adverse-selection | B35: Adverse Selection | C35: Anti-Selection | D35: Underwriting | E35: All | F35: When people who are more likely to have a loss are more likely to buy insurance, making the pool riskier. | G35: People who know they need surgery sign up for health insurance right before. | H35: Underwriting system | I35: Underwriters, Product Owners | J35: Intermediate | K35: Medium | L35: underwriting, open-enrollment-period, individual-mandate
A36: aerial-imagery | B36: Aerial Imagery | D36: Technology | E36: Property, Commercial | F36: Satellite or aircraft images used to assess roofs, trees and hazards without visiting. | G36: An insurer spots a damaged roof from imagery. | H36: Underwriting system | I36: Developers, Underwriters | J36: Intermediate | K36: Low | L36: inspection, third-party-data | M36: Some states restrict non-renewals based solely on aerial images.
A37: affinity-group | B37: Affinity Group | C37: Affinity Program | D37: Distribution | E37: All | F37: Insurance sold to members of an organization, like alumni or professional associations, often at group rates. | G37: A bar association sponsors a professional liability program. | I37: Underwriters, Product Owners | J37: Intermediate | K37: Low | L37: group-insurance, embedded-insurance
A38: affordable-care-act | B38: Affordable Care Act | C38: ACA; Obamacare | D38: Regulation | E38: Health | F38: A 2010 federal law that reformed US health insurance, including marketplaces, subsidies, essential benefits and bans on pre-existing condition exclusions. | G38: You can't be denied a plan because of diabetes. | H38: Regulatory filings | I38: Individuals, Developers, Underwriters, Product Owners | J38: Beginner | K38: High | L38: health-insurance-marketplace, essential-health-benefits, pre-existing-condition, premium-tax-credit
A39: age-nearest-birthday | B39: Age Nearest Birthday | C39: ANB; Age Last Birthday (ALB) | D39: Underwriting | E39: Life | F39: Two ways insurers define age: the age at your nearest birthday, or at your last birthday. | G39: At 35 and 7 months you're 36 ANB but 35 ALB. | H39: Rating engine | I39: Developers, Underwriters | J39: Advanced | K39: Low | L39: issue-age
A40: agency-bill | B40: Agency Bill | D40: Distribution | E40: Property, Casualty/Liability, Commercial | F40: The agent bills and collects premium from the client, then pays the insurer net of commission. | G40: A commercial client pays the agency, not the carrier. | H40: Billing statement | I40: Developers, Underwriters | J40: Intermediate | K40: Medium | L40: direct-bill
...

Sheet By Category
A1: Glossary Counts
A2: All counts are live formulas over the Terms sheet.
A4: Total terms | B4: =COUNTA(Terms!$A$2:$A$1017) -> 1016
A6: Category | B6: Terms | C6: % of Total | D6: Description
A7: Core Concept | B7: =COUNTIF(Terms!$D$2:$D$1017,"Core Concept") -> 55 | C7: =IF($B$4=0,0,B7/$B$4) -> 0.054133858 | D7: Foundational ideas that apply across insurance (premium, indemnity, risk, liability).
A8: Policy Wording | B8: =COUNTIF(Terms!$D$2:$D$1017,"Policy Wording") -> 158 | C8: =IF($B$4=0,0,B8/$B$4) -> 0.15551181 | D8: Parts, clauses and phrases found in the policy contract itself.
A9: Lifecycle | B9: =COUNTIF(Terms!$D$2:$D$1017,"Lifecycle") -> 40 | C9: =IF($B$4=0,0,B9/$B$4) -> 0.039370079 | D9: Stages and transactions in a policy's life: quote, bind, issue, change, renew, cancel.
A10: Underwriting | B10: =COUNTIF(Terms!$D$2:$D$1017,"Underwriting") -> 78 | C10: =IF($B$4=0,0,B10/$B$4) -> 0.076771654 | D10: Evaluating, selecting and pricing risks.
A11: Claims | B11: =COUNTIF(Terms!$D$2:$D$1017,"Claims") -> 59 | C11: =IF($B$4=0,0,B11/$B$4) -> 0.058070866 | D11: Reporting, investigating, valuing and settling losses.
A12: Distribution | B12: =COUNTIF(Terms!$D$2:$D$1017,"Distribution") -> 40 | C12: =IF($B$4=0,0,B12/$B$4) -> 0.039370079 | D12: How insurance is sold: agents, brokers, MGAs, channels and commissions.
A13: Finance & Actuarial | B13: =COUNTIF(Terms!$D$2:$D$1017,"Finance & Actuarial") -> 93 | C13: =IF($B$4=0,0,B13/$B$4) -> 0.091535433 | D13: Accounting, reserving, pricing math and financial metrics.
A14: Regulation | B14: =COUNTIF(Terms!$D$2:$D$1017,"Regulation") -> 91 | C14: =IF($B$4=0,0,B14/$B$4) -> 0.089566929 | D14: US federal and state laws, regulators and compliance requirements.
A15: Reinsurance | B15: =COUNTIF(Terms!$D$2:$D$1017,"Reinsurance") -> 41 | C15: =IF($B$4=0,0,B15/$B$4) -> 0.040354331 | D15: Insurance for insurers, layers, treaties and capital-market risk transfer structures.
A16: Legal/Latin | B16: =COUNTIF(Terms!$D$2:$D$1017,"Legal/Latin") -> 49 | C16: =IF($B$4=0,0,B16/$B$4) -> 0.048228346 | D16: Legal doctrines and Latin phrases seen in policies, claims and court decisions.
A17: Technology | B17: =COUNTIF(Terms!$D$2:$D$1017,"Technology") -> 62 | C17: =IF($B$4=0,0,B17/$B$4) -> 0.061023622 | D17: Systems, data standards and codes developers meet on insurance projects.
A18: Line-Specific | B18: =COUNTIF(Terms!$D$2:$D$1017,"Line-Specific") -> 250 | C18: =IF($B$4=0,0,B18/$B$4) -> 0.24606299 | D18: Terms that belong mainly to one line of insurance (life, health, auto, marine, cyber, crop, etc.).
A19: Subtotal | B19: =SUM(B7:B18) -> 1016
A21: Applies To Line | B21: Terms | C21: % of Total | D21: Description
A22: All | B22: =COUNTIF(Terms!$E$2:$E$1017,"All") -> 318 | C22: =IF($B$4=0,0,B22/$B$4) -> 0.31299213 | D22: Applies across all lines of insurance.
A23: Life | B23: =COUNTIF(Terms!$E$2:$E$1017,"*Life*") -> 144 | C23: =IF($B$4=0,0,B23/$B$4) -> 0.14173228 | D23: Life insurance and annuities.
A24: Health | B24: =COUNTIF(Terms!$E$2:$E$1017,"*Health*") -> 163 | C24: =IF($B$4=0,0,B24/$B$4) -> 0.16043307 | D24: Medical, dental, vision, disability, long-term care and supplemental health.
A25: Property | B25: =COUNTIF(Terms!$E$2:$E$1017,"*Property*") -> 186 | C25: =IF($B$4=0,0,B25/$B$4) -> 0.18307087 | D25: Homes, buildings, contents, flood, earthquake and other property.
A26: Casualty/Liability | B26: =COUNTIF(Terms!$E$2:$E$1017,"*Casualty/Liability*") -> 124 | C26: =IF($B$4=0,0,B26/$B$4) -> 0.12204724 | D26: Legal liability to others: general, product, umbrella, workers' comp liability, etc.
A27: Motor | B27: =COUNTIF(Terms!$E$2:$E$1017,"*Motor*") -> 112 | C27: =IF($B$4=0,0,B27/$B$4) -> 0.11023622 | D27: Personal and commercial auto.
A28: Commercial | B28: =COUNTIF(Terms!$E$2:$E$1017,"*Commercial*") -> 168 | C28: =IF($B$4=0,0,B28/$B$4) -> 0.16535433 | D28: Business insurance packages and coverages.
A29: Marine/Aviation/Transit | B29: =COUNTIF(Terms!$E$2:$E$1017,"*Marine/Aviation/Transit*") -> 46 | C29: =IF($B$4=0,0,B29/$B$4) -> 0.045275591 | D29: Ocean and inland marine, cargo, hull, aviation and goods in transit.
A30: Specialty | B30: =COUNTIF(Terms!$E$2:$E$1017,"*Specialty*") -> 61 | C30: =IF($B$4=0,0,B30/$B$4) -> 0.06003937 | D30: Niche risks: travel, pet, event, title, K&R, space, etc.
A31: Financial Lines | B31: =COUNTIF(Terms!$E$2:$E$1017,"*Financial Lines*") -> 81 | C31: =IF($B$4=0,0,B31/$B$4) -> 0.079724409 | D31: D&O, E&O/professional, cyber, crime, fidelity, surety, credit and mortgage.
A32: Agriculture | B32: =COUNTIF(Terms!$E$2:$E$1017,"*Agriculture*") -> 22 | C32: =IF($B$4=0,0,B32/$B$4) -> 0.021653543 | D32: Crop, livestock and farm insurance.
A33: Social/Government | B33: =COUNTIF(Terms!$E$2:$E$1017,"*Social/Government*") -> 28 | C33: =IF($B$4=0,0,B33/$B$4) -> 0.027559055 | D33: Government and social programs: Medicare, Medicaid, NFIP, SSDI, unemployment, state funds.
A34: Reinsurance | B34: =COUNTIF(Terms!$E$2:$E$1017,"*Reinsurance*") -> 57 | C34: =IF($B$4=0,0,B34/$B$4) -> 0.056102362 | D34: Insurance bought by insurers.
A35: Alternative Risk Transfer | B35: =COUNTIF(Terms!$E$2:$E$1017,"*Alternative Risk Transfer*") -> 14 | C35: =IF($B$4=0,0,B35/$B$4) -> 0.013779528 | D35: Captives, risk retention groups, cat bonds, ILS and parametric structures.
A36: A term can apply to several lines, so line counts overlap and do not sum to the total. 'All' counts terms tagged as applying to every line.
A38: Difficulty | B38: Terms | C38: % of Total | D38: Description
A39: Beginner | B39: =COUNTIF(Terms!$J$2:$J$1017,"Beginner") -> 230 | C39: =IF($B$4=0,0,B39/$B$4) -> 0.22637795 | D39: Everyday terms most policyholders will see.
A40: Intermediate | B40: =COUNTIF(Terms!$J$2:$J$1017,"Intermediate") -> 471 | C40: =IF($B$4=0,0,B40/$B$4) -> 0.46358268 | D40: Common professional terms; some industry context helps.
A41: Advanced | B41: =COUNTIF(Terms!$J$2:$J$1017,"Advanced") -> 315 | C41: =IF($B$4=0,0,B41/$B$4) -> 0.31003937 | D41: Specialist terms used by underwriters, actuaries, lawyers or reinsurance professionals.
A42: Subtotal | B42: =SUM(B39:B41) -> 1016
A44: Usage Frequency | B44: Terms | C44: % of Total | D44: Description
A45: High | B45: =COUNTIF(Terms!$K$2:$K$1017,"High") -> 142 | C45: =IF($B$4=0,0,B45/$B$4) -> 0.13976378 | D45: Everyday words almost everyone in US insurance meets constantly (policy, premium, claim, deductible, renewal).
...

Sheet README
A1: US Insurance Glossary
A2: Purpose | B2: Plain-English glossary of US insurance terms for people new to insurance: policyholders reading their policy, developers joining insurance projects, new underwriters and product owners. Built to be loaded into the learning app as glossary entries (see data/insurance-glossary.csv, which mirrors the Terms sheet).
A3: Scope | B3: US market only: US terminology, definitions and regulation (NAIC, state departments of insurance, admitted vs non-admitted/surplus lines, ACA, COBRA, ERISA, HIPAA, Medicare/Medicaid, ISO forms, NFIP, TRIA, federal crop insurance). Terms used only outside the US are excluded.
A4: Accuracy note | B4: Definitions are simplified for learning. Policy wording, state law and court decisions control actual coverage; always check the specific policy and state rules. State-specific facts in 'US Notes' reflect general knowledge as of 2026 and can change.
A5: Sorting | B5: Terms sheet is sorted alphabetically by Term (case-insensitive).
A7: COLUMNS (Terms sheet)
A8: ID | B8: Unique, stable, lowercase slug (a-z, 0-9, hyphens). Use as the primary key in the app.
A9: Term | B9: The term as it is most commonly written in the US.
A10: Also Known As | B10: Synonyms, abbreviations and acronym expansions, separated by semicolons (;). Alternative names are listed here rather than as separate rows.
A11: Category | B11: Exactly one value from the Category vocabulary below.
A12: Applies To Lines | B12: Comma-separated values from the Lines vocabulary below. 'All' means the term is general and applies across lines (used alone).
A13: Plain-English Definition | B13: One or two simple sentences, avoiding jargon. Never empty.
A14: Example | B14: A concrete, realistic illustration. Dollar figures are illustrative only.
A15: Where You'll See It | B15: Comma-separated values from the Where vocabulary below; may be blank for general concepts.
A16: Most Relevant For | B16: Comma-separated values from the Audience vocabulary below.
A17: Difficulty | B17: One value: Beginner, Intermediate or Advanced. How hard the term is to understand.
A18: Usage Frequency | B18: One value: High, Medium or Low. How often the term appears across US policy documents, quotes, claims and everyday industry work. Independent of Difficulty: a simple term can be Low and a technical one High. Never empty.
A19: Related Terms | B19: Comma-separated IDs of other rows in this sheet. Every ID is validated to exist.
A20: US Notes | B20: US-specific details such as state-by-state variations, federal rules or regulator names. Blank when not applicable.
A22: VOCABULARY: Category
A23: Core Concept | B23: Foundational ideas that apply across insurance (premium, indemnity, risk, liability).
A24: Policy Wording | B24: Parts, clauses and phrases found in the policy contract itself.
A25: Lifecycle | B25: Stages and transactions in a policy's life: quote, bind, issue, change, renew, cancel.
A26: Underwriting | B26: Evaluating, selecting and pricing risks.
A27: Claims | B27: Reporting, investigating, valuing and settling losses.
A28: Distribution | B28: How insurance is sold: agents, brokers, MGAs, channels and commissions.
A29: Finance & Actuarial | B29: Accounting, reserving, pricing math and financial metrics.
A30: Regulation | B30: US federal and state laws, regulators and compliance requirements.
A31: Reinsurance | B31: Insurance for insurers, layers, treaties and capital-market risk transfer structures.
A32: Legal/Latin | B32: Legal doctrines and Latin phrases seen in policies, claims and court decisions.
A33: Technology | B33: Systems, data standards and codes developers meet on insurance projects.
A34: Line-Specific | B34: Terms that belong mainly to one line of insurance (life, health, auto, marine, cyber, crop, etc.).
A36: VOCABULARY: Applies To Lines
A37: All | B37: Applies across all lines of insurance.
A38: Life | B38: Life insurance and annuities.
A39: Health | B39: Medical, dental, vision, disability, long-term care and supplemental health.
A40: Property | B40: Homes, buildings, contents, flood, earthquake and other property.
A41: Casualty/Liability | B41: Legal liability to others: general, product, umbrella, workers' comp liability, etc.
A42: Motor | B42: Personal and commercial auto.
A43: Commercial | B43: Business insurance packages and coverages.
...
