Workbook

Sheet Tree
A1: ID | B1: Parent ID | C1: Level | D1: Name | E1: Also Known As | F1: Plain-English Description | G1: Example | H1: Personal/Commercial/Both | I1: US Notes | J1: Full Path
A2: life | C2: 1 | D2: Life Insurance | E2: Life coverage | F2: Pays money to chosen people (beneficiaries) when the insured person dies, and some types also build cash value you can use while alive. | G2: A parent buys a policy so their family can pay off the mortgage and college costs if the parent dies. | H2: Personal | I2: Regulated by states; policy forms filed with each state insurance department. State guaranty associations protect policyholders if an insurer fails (typically at least $300,000 death benefit). | J2: Life Insurance
A3: life.term | B3: life | C3: 2 | D3: Term Life | E3: Temporary life insurance | F3: Covers you only for a fixed period, such as 10, 20 or 30 years, and pays out only if you die within that period. It has no cash value, which makes it the cheapest life cover. | G3: A 30-year-old buys a 30-year term policy that matches the length of their mortgage. | H3: Personal | I3: The most common individual life product sold in the US by policy count. | J3: Life Insurance > Term Life
A4: life.term.level | B4: life.term | C4: 3 | D4: Level Term | E4: Guaranteed level term | F4: The death benefit and premium stay the same for the whole term (e.g. 10, 15, 20 or 30 years). | G4: A family buys $500,000 of cover that stays at $500,000 for 20 years. | H4: Personal | J4: Life Insurance > Term Life > Level Term
A5: life.term.decreasing | B5: life.term | C5: 3 | D5: Decreasing Term | E5: Mortgage protection insurance | F5: The death benefit shrinks over time, usually in line with a mortgage balance. | G5: A couple buys cover that falls each year as their mortgage is paid down. | H5: Personal | I5: Often marketed by mortgage servicers via direct mail. | J5: Life Insurance > Term Life > Decreasing Term
A6: life.term.art | B6: life.term | C6: 3 | D6: Annually Renewable Term (ART) | E6: Yearly renewable term (YRT) | F6: One-year cover that can be renewed each year without a new medical exam, with the premium rising as you age. | G6: A person needs cover for a short, uncertain period and renews year by year. | H6: Personal | I6: YRT is also the most common basis for life reinsurance. | J6: Life Insurance > Term Life > Annually Renewable Term (ART)
A7: life.term.convertible | B7: life.term | C7: 3 | D7: Convertible Term | F7: Term cover that can be switched into a permanent policy later without new medical questions. | G7: Someone buys cheap term cover now, planning to convert to whole life when their income grows. | H7: Personal | I7: Most US level term policies include a conversion privilege up to a set age. | J7: Life Insurance > Term Life > Convertible Term
A8: life.term.rop | B8: life.term | C8: 3 | D8: Return of Premium Term (ROP) | F8: Term cover that refunds the premiums you paid if you are still alive at the end of the term. It costs more than plain term. | G8: A buyer who dislikes "wasting" premiums picks a policy that returns them at the end of 30 years. | H8: Personal | J8: Life Insurance > Term Life > Return of Premium Term (ROP)
A9: life.term.credit_life | B9: life.term | C9: 3 | D9: Credit Life Insurance | E9: Credit insurance | F9: Pays off a specific loan if the borrower dies; often offered by the lender at the time of the loan. | G9: A car buyer is offered a policy that clears the auto loan if the buyer dies. | H9: Personal | I9: Rates and sales practices are tightly regulated by states; must be optional for the borrower. | J9: Life Insurance > Term Life > Credit Life Insurance
A10: life.permanent | B10: life | C10: 2 | D10: Permanent Life | E10: Cash value life insurance | F10: Covers you for your whole life as long as premiums are paid, and most types build a cash value you can borrow against or withdraw. | G10: A business owner buys permanent cover to leave money to heirs regardless of when they die. | H10: Personal | I10: Cash value grows tax-deferred if the policy meets the IRC Section 7702 definition of life insurance; overfunded policies become Modified Endowment Contracts (MECs). | J10: Life Insurance > Permanent Life
A11: life.permanent.whole | B11: life.permanent | C11: 3 | D11: Whole Life | E11: Ordinary life; Straight life | F11: Lifelong cover with fixed premiums, a guaranteed death benefit and a guaranteed cash value that grows slowly. | G11: A grandparent buys a whole life policy to leave a guaranteed sum to grandchildren. | H11: Personal | J11: Life Insurance > Permanent Life > Whole Life
A12: life.permanent.whole.participating | B12: life.permanent.whole | C12: 4 | D12: Participating Whole Life | E12: Par whole life; Dividend-paying whole life | F12: Whole life that may pay yearly dividends from the insurer's surplus, which can buy paid-up additions, reduce premiums or be taken as cash. | G12: A policyholder uses dividends from a mutual insurer to buy paid-up additions. | H12: Personal | I12: Sold mainly by mutual insurers (e.g. Northwestern Mutual, MassMutual, New York Life). Dividends are not guaranteed. | J12: Life Insurance > Permanent Life > Whole Life > Participating Whole Life
A13: life.permanent.whole.non_participating | B13: life.permanent.whole | C13: 4 | D13: Non-Participating Whole Life | E13: Non-par whole life | F13: Whole life with fixed guarantees and no dividends, usually at a lower premium. | G13: A buyer wants predictable costs without dividends. | H13: Personal | J13: Life Insurance > Permanent Life > Whole Life > Non-Participating Whole Life
A14: life.permanent.whole.limited_pay | B14: life.permanent.whole | C14: 4 | D14: Limited Pay Whole Life | E14: 10-pay; 20-pay; Paid-up at 65 | F14: Whole life where premiums are paid for a set number of years or until a certain age, but cover lasts for life. | G14: A 40-year-old pays for 20 years so nothing is owed in retirement. | H14: Personal | J14: Life Insurance > Permanent Life > Whole Life > Limited Pay Whole Life
A15: life.permanent.whole.single_premium | B15: life.permanent.whole | C15: 4 | D15: Single Premium Whole Life (SPWL) | F15: Whole life bought with one lump-sum payment. | G15: A retiree moves an inheritance into a single-premium policy for their heirs. | H15: Personal | I15: Usually a Modified Endowment Contract (MEC), so loans and withdrawals are taxed less favorably. | J15: Life Insurance > Permanent Life > Whole Life > Single Premium Whole Life (SPWL)
A16: life.permanent.whole.final_expense | B16: life.permanent.whole | C16: 4 | D16: Final Expense Insurance | E16: Burial insurance; Funeral insurance | F16: Small whole life policy (often $5,000-$25,000), with simplified medical questions, meant to cover funeral and end-of-life costs. | G16: A 70-year-old buys $10,000 of cover so their children won't have to pay for the funeral. | H16: Personal | I16: Heavily marketed to seniors aged 50-85. | J16: Life Insurance > Permanent Life > Whole Life > Final Expense Insurance
A17: life.permanent.whole.guaranteed_issue | B17: life.permanent.whole | C17: 4 | D17: Guaranteed Issue Whole Life | E17: Guaranteed acceptance life | F17: Whole life that accepts anyone in the eligible age range with no health questions; benefits are usually limited in the first two years (a "graded" death benefit). | G17: A person with serious health conditions who can't qualify elsewhere buys a small guaranteed policy. | H17: Personal | J17: Life Insurance > Permanent Life > Whole Life > Guaranteed Issue Whole Life
A18: life.permanent.whole.industrial | B18: life.permanent.whole | C18: 4 | D18: Industrial / Home Service Life | E18: Debit life | F18: Very small whole life policies historically sold door to door with weekly or monthly premium collection. | G18: A family in the 1950s paid a collector each week for a small burial policy. | H18: Personal | I18: Largely a legacy product; few new sales today. | J18: Life Insurance > Permanent Life > Whole Life > Industrial / Home Service Life
A19: life.permanent.universal | B19: life.permanent | C19: 3 | D19: Universal Life (UL) | E19: Flexible premium adjustable life | F19: Permanent cover with flexible premiums and an adjustable death benefit; the cash value earns interest credited in different ways depending on the type. | G19: A self-employed person with uneven income varies their payments each year. | H19: Personal | J19: Life Insurance > Permanent Life > Universal Life (UL)
A20: life.permanent.universal.current_assumption | B20: life.permanent.universal | C20: 4 | D20: Current Assumption Universal Life | E20: Traditional UL; Fixed UL | F20: The cash value earns an interest rate declared by the insurer, with a minimum guaranteed rate. | G20: A buyer wants flexible permanent cover with steady, insurer-declared interest. | H20: Personal | J20: Life Insurance > Permanent Life > Universal Life (UL) > Current Assumption Universal Life
A21: life.permanent.universal.gul | B21: life.permanent.universal | C21: 4 | D21: Guaranteed Universal Life (GUL) | E21: No-lapse guarantee UL | F21: UL built mainly for a guaranteed lifelong death benefit at the lowest cost, with little cash value. | G21: A retiree wants guaranteed cover to age 100+ for estate planning at a lower price than whole life. | H21: Personal | I21: Popular for estate planning; reserves governed by NAIC Actuarial Guideline 38 (AXXX). | J21: Life Insurance > Permanent Life > Universal Life (UL) > Guaranteed Universal Life (GUL)
A22: life.permanent.universal.iul | B22: life.permanent.universal | C22: 4 | D22: Indexed Universal Life (IUL) | E22: Equity-indexed UL; Fixed indexed UL | F22: Cash value earns interest linked to a stock market index (e.g. the S&P 500), subject to a cap and a floor (often 0%), so it doesn't lose value from market drops. | G22: A buyer wants some market-linked growth in their policy without direct stock market losses. | H22: Personal | I22: Illustrations are regulated by NAIC Actuarial Guideline 49-A. Not a registered security. | J22: Life Insurance > Permanent Life > Universal Life (UL) > Indexed Universal Life (IUL)
A23: life.permanent.universal.vul | B23: life.permanent.universal | C23: 4 | D23: Variable Universal Life (VUL) | F23: Cash value is invested in sub-accounts similar to mutual funds, so it can grow or lose value. | G23: An investor comfortable with risk picks equity funds inside their life policy. | H23: Personal | I23: Regulated as a security: sold with a prospectus by FINRA-registered representatives. | J23: Life Insurance > Permanent Life > Universal Life (UL) > Variable Universal Life (VUL)
A24: life.permanent.universal.survivorship | B24: life.permanent.universal | C24: 4 | D24: Survivorship Universal Life | E24: Second-to-die; Joint and last survivor | F24: Covers two people (usually spouses) and pays out only after both have died. | G24: A wealthy couple buys cover to pay estate taxes their heirs will owe after both die. | H24: Personal | I24: Often owned by an Irrevocable Life Insurance Trust (ILIT) to keep proceeds out of the taxable estate. | J24: Life Insurance > Permanent Life > Universal Life (UL) > Survivorship Universal Life
A25: life.permanent.variable_life | B25: life.permanent | C25: 3 | D25: Variable Life | E25: Variable whole life | F25: Permanent cover with fixed premiums where the cash value and possibly the death benefit depend on investment performance. | G25: A policyholder chooses investment sub-accounts inside a fixed-premium policy. | H25: Personal | I25: Regulated as a security (SEC/FINRA) as well as by state insurance departments. | J25: Life Insurance > Permanent Life > Variable Life
A26: life.annuities | B26: life | C26: 2 | D26: Annuities | F26: Turns a lump sum or series of payments into a stream of income, often for life. Annuities protect against outliving your savings rather than dying early. | G26: A retiree uses part of their savings to buy guaranteed monthly income for life. | H26: Personal | I26: Sold by life insurers; earnings grow tax-deferred. Fixed annuities are state-regulated; variable and registered index-linked annuities are also SEC/FINRA-regulated. | J26: Life Insurance > Annuities
A27: life.annuities.immediate | B27: life.annuities | C27: 3 | D27: Immediate Annuity | E27: Single Premium Immediate Annuity (SPIA); Income annuity | F27: A lump sum is paid in and income starts right away, usually within a year. | G27: A 67-year-old pays $200,000 and receives about $1,200 a month for life. | H27: Personal | J27: Life Insurance > Annuities > Immediate Annuity
A28: life.annuities.deferred | B28: life.annuities | C28: 3 | D28: Deferred Annuity | F28: Money grows for years before income starts. | G28: A 50-year-old invests now to start income at 65. | H28: Personal | I28: Withdrawals before age 59 1/2 usually face a 10% IRS penalty on earnings. | J28: Life Insurance > Annuities > Deferred Annuity
A29: life.annuities.deferred.fixed | B29: life.annuities.deferred | C29: 4 | D29: Fixed Annuity | E29: Multi-Year Guaranteed Annuity (MYGA) | F29: Earns a guaranteed fixed interest rate for a set period. | G29: A cautious saver locks in a 5% rate for 5 years. | H29: Personal | J29: Life Insurance > Annuities > Deferred Annuity > Fixed Annuity
A30: life.annuities.deferred.fia | B30: life.annuities.deferred | C30: 4 | D30: Fixed Indexed Annuity (FIA) | E30: Equity-indexed annuity | F30: Interest is linked to a market index with a cap and a zero floor, so principal isn't lost to market drops. | G30: A pre-retiree wants some index-linked growth with no loss of principal. | H30: Personal | I30: State-regulated insurance product, not a security. | J30: Life Insurance > Annuities > Deferred Annuity > Fixed Indexed Annuity (FIA)
A31: life.annuities.deferred.variable | B31: life.annuities.deferred | C31: 4 | D31: Variable Annuity | F31: Money is invested in sub-accounts, so value can rise or fall; optional riders can guarantee income or a death benefit. | G31: An investor holds funds inside a variable annuity with a lifetime income rider. | H31: Personal | I31: Sold with a prospectus; FINRA Rule 2330 governs suitability. | J31: Life Insurance > Annuities > Deferred Annuity > Variable Annuity
A32: life.annuities.deferred.variable.gmdb | B32: life.annuities.deferred.variable | C32: 5 | D32: Guaranteed Minimum Death Benefit (GMDB) | E32: Enhanced death benefit | F32: A variable annuity rider guaranteeing heirs receive at least a set amount (e.g. premiums paid or a high-water mark) even if investments fell. | G32: Markets drop 30% but the owner's heirs still get the full amount invested. | H32: Personal | J32: Life Insurance > Annuities > Deferred Annuity > Variable Annuity > Guaranteed Minimum Death Benefit (GMDB)
A33: life.annuities.deferred.variable.glwb | B33: life.annuities.deferred.variable | C33: 5 | D33: Guaranteed Lifetime Withdrawal Benefit (GLWB) | E33: GMWB; Lifetime income rider | F33: A rider that lets you withdraw a set percentage each year for life, even if the account value runs out. | G33: A retiree withdraws 5% of a $400,000 benefit base every year for life. | H33: Personal | I33: The most common living benefit rider on US variable and indexed annuities. | J33: Life Insurance > Annuities > Deferred Annuity > Variable Annuity > Guaranteed Lifetime Withdrawal Benefit (GLWB)
A34: life.annuities.deferred.variable.gmib | B34: life.annuities.deferred.variable | C34: 5 | D34: Guaranteed Minimum Income Benefit (GMIB) | F34: A rider guaranteeing a minimum level of lifetime income if the contract is annuitized after a waiting period. | G34: An owner annuitizes at 70 using a guaranteed income base. | H34: Personal | I34: Less widely sold today than GLWBs. | J34: Life Insurance > Annuities > Deferred Annuity > Variable Annuity > Guaranteed Minimum Income Benefit (GMIB)
A35: life.annuities.deferred.variable.gmab | B35: life.annuities.deferred.variable | C35: 5 | D35: Guaranteed Minimum Accumulation Benefit (GMAB) | F35: A rider guaranteeing the account will be worth at least a set amount after a waiting period, such as 10 years. | G35: After 10 years the account is topped up to the original premium. | H35: Personal | J35: Life Insurance > Annuities > Deferred Annuity > Variable Annuity > Guaranteed Minimum Accumulation Benefit (GMAB)
A36: life.annuities.deferred.rila | B36: life.annuities.deferred | C36: 4 | D36: Registered Index-Linked Annuity (RILA) | E36: Buffered annuity; Structured annuity | F36: Index-linked returns with a buffer or floor that limits (but does not remove) losses, in exchange for higher caps. | G36: A saver accepts losses beyond -10% in exchange for a higher upside cap. | H36: Personal | I36: SEC-registered; one of the fastest-growing US annuity categories since 2020. | J36: Life Insurance > Annuities > Deferred Annuity > Registered Index-Linked Annuity (RILA)
A37: life.annuities.deferred.qlac | B37: life.annuities.deferred | C37: 4 | D37: Qualified Longevity Annuity Contract (QLAC) | E37: Longevity annuity | F37: A deferred annuity bought with retirement account (e.g. IRA, 401(k)) money that can start paying as late as age 85. | G37: A retiree uses part of an IRA to guarantee income from age 85. | H37: Personal | I37: Premium limit set by IRS (indexed; $200,000 after SECURE 2.0). Excluded from required minimum distributions until payments start. | J37: Life Insurance > Annuities > Deferred Annuity > Qualified Longevity Annuity Contract (QLAC)
A38: life.annuities.joint | B38: life.annuities | C38: 3 | D38: Joint and Survivor Annuity | F38: Keeps paying income while either of two people is alive, sometimes at a reduced rate after the first dies. | G38: A married couple buys an annuity that pays until the second spouse dies. | H38: Personal | I38: ERISA requires this as the default form for married participants in many pension plans. | J38: Life Insurance > Annuities > Joint and Survivor Annuity
A39: life.annuities.structured_settlement | B39: life.annuities | C39: 3 | D39: Structured Settlement Annuity | F39: An annuity used to pay a lawsuit or injury settlement as a stream of payments instead of a lump sum. | G39: An injury victim receives monthly payments for 30 years from a settlement. | H39: Personal | I39: Payments for physical injury are generally tax-free under IRC Section 104. | J39: Life Insurance > Annuities > Structured Settlement Annuity
A40: life.annuities.pension_risk_transfer | B40: life.annuities | C40: 3 | D40: Pension Risk Transfer (Group Annuity) | E40: Pension buyout; Group annuity contract | F40: An employer pays an insurer to take over its pension obligations, and the insurer pays retirees' pensions. | G40: A manufacturer transfers its retirees' pensions to a life insurer. | H40: Commercial | I40: Governed by ERISA and Department of Labor Interpretive Bulletin 95-1 on selecting annuity providers. | J40: Life Insurance > Annuities > Pension Risk Transfer (Group Annuity)
...

Sheet Outline
A1: Level 1 | B1: Level 2 | C1: Level 3 | D1: Level 4 | E1: Level 5 | F1: ID
A2: Life Insurance | F2: life
B3: Term Life | F3: life.term
C4: Level Term | F4: life.term.level
C5: Decreasing Term | F5: life.term.decreasing
C6: Annually Renewable Term (ART) | F6: life.term.art
C7: Convertible Term | F7: life.term.convertible
C8: Return of Premium Term (ROP) | F8: life.term.rop
C9: Credit Life Insurance | F9: life.term.credit_life
B10: Permanent Life | F10: life.permanent
C11: Whole Life | F11: life.permanent.whole
D12: Participating Whole Life | F12: life.permanent.whole.participating
D13: Non-Participating Whole Life | F13: life.permanent.whole.non_participating
D14: Limited Pay Whole Life | F14: life.permanent.whole.limited_pay
D15: Single Premium Whole Life (SPWL) | F15: life.permanent.whole.single_premium
D16: Final Expense Insurance | F16: life.permanent.whole.final_expense
D17: Guaranteed Issue Whole Life | F17: life.permanent.whole.guaranteed_issue
D18: Industrial / Home Service Life | F18: life.permanent.whole.industrial
C19: Universal Life (UL) | F19: life.permanent.universal
D20: Current Assumption Universal Life | F20: life.permanent.universal.current_assumption
D21: Guaranteed Universal Life (GUL) | F21: life.permanent.universal.gul
D22: Indexed Universal Life (IUL) | F22: life.permanent.universal.iul
D23: Variable Universal Life (VUL) | F23: life.permanent.universal.vul
D24: Survivorship Universal Life | F24: life.permanent.universal.survivorship
C25: Variable Life | F25: life.permanent.variable_life
B26: Annuities | F26: life.annuities
C27: Immediate Annuity | F27: life.annuities.immediate
C28: Deferred Annuity | F28: life.annuities.deferred
D29: Fixed Annuity | F29: life.annuities.deferred.fixed
D30: Fixed Indexed Annuity (FIA) | F30: life.annuities.deferred.fia
D31: Variable Annuity | F31: life.annuities.deferred.variable
E32: Guaranteed Minimum Death Benefit (GMDB) | F32: life.annuities.deferred.variable.gmdb
E33: Guaranteed Lifetime Withdrawal Benefit (GLWB) | F33: life.annuities.deferred.variable.glwb
E34: Guaranteed Minimum Income Benefit (GMIB) | F34: life.annuities.deferred.variable.gmib
E35: Guaranteed Minimum Accumulation Benefit (GMAB) | F35: life.annuities.deferred.variable.gmab
D36: Registered Index-Linked Annuity (RILA) | F36: life.annuities.deferred.rila
D37: Qualified Longevity Annuity Contract (QLAC) | F37: life.annuities.deferred.qlac
C38: Joint and Survivor Annuity | F38: life.annuities.joint
C39: Structured Settlement Annuity | F39: life.annuities.structured_settlement
C40: Pension Risk Transfer (Group Annuity) | F40: life.annuities.pension_risk_transfer
...

Sheet Summary
A1: Insurance Taxonomy (US) - Summary
A3: Root category | B3: Root ID | C3: Nodes (incl. root) | D3: Max depth
A4: Life Insurance | B4: life | C4: =COUNTIF(Tree!$A:$A,B4)+COUNTIF(Tree!$A:$A,B4&".*") -> 58 | D4: =MAX(1,_xlfn.MAXIFS(Tree!$C:$C,Tree!$A:$A,B4&".*")) -> 5
A5: Health Insurance | B5: health | C5: =COUNTIF(Tree!$A:$A,B5)+COUNTIF(Tree!$A:$A,B5&".*") -> 69 | D5: =MAX(1,_xlfn.MAXIFS(Tree!$C:$C,Tree!$A:$A,B5&".*")) -> 5
A6: Personal Property Insurance | B6: property | C6: =COUNTIF(Tree!$A:$A,B6)+COUNTIF(Tree!$A:$A,B6&".*") -> 39 | D6: =MAX(1,_xlfn.MAXIFS(Tree!$C:$C,Tree!$A:$A,B6&".*")) -> 4
A7: Casualty & Liability Insurance | B7: casualty | C7: =COUNTIF(Tree!$A:$A,B7)+COUNTIF(Tree!$A:$A,B7&".*") -> 43 | D7: =MAX(1,_xlfn.MAXIFS(Tree!$C:$C,Tree!$A:$A,B7&".*")) -> 4
A8: Auto Insurance | B8: auto | C8: =COUNTIF(Tree!$A:$A,B8)+COUNTIF(Tree!$A:$A,B8&".*") -> 45 | D8: =MAX(1,_xlfn.MAXIFS(Tree!$C:$C,Tree!$A:$A,B8&".*")) -> 4
A9: Commercial Lines (Business Property & Packages) | B9: commercial | C9: =COUNTIF(Tree!$A:$A,B9)+COUNTIF(Tree!$A:$A,B9&".*") -> 29 | D9: =MAX(1,_xlfn.MAXIFS(Tree!$C:$C,Tree!$A:$A,B9&".*")) -> 4
A10: Marine, Aviation & Transit | B10: marine | C10: =COUNTIF(Tree!$A:$A,B10)+COUNTIF(Tree!$A:$A,B10&".*") -> 44 | D10: =MAX(1,_xlfn.MAXIFS(Tree!$C:$C,Tree!$A:$A,B10&".*")) -> 4
A11: Specialty Insurance | B11: specialty | C11: =COUNTIF(Tree!$A:$A,B11)+COUNTIF(Tree!$A:$A,B11&".*") -> 72 | D11: =MAX(1,_xlfn.MAXIFS(Tree!$C:$C,Tree!$A:$A,B11&".*")) -> 4
A12: Financial Lines | B12: financial | C12: =COUNTIF(Tree!$A:$A,B12)+COUNTIF(Tree!$A:$A,B12&".*") -> 44 | D12: =MAX(1,_xlfn.MAXIFS(Tree!$C:$C,Tree!$A:$A,B12&".*")) -> 4
A13: Agricultural & Crop Insurance | B13: agriculture | C13: =COUNTIF(Tree!$A:$A,B13)+COUNTIF(Tree!$A:$A,B13&".*") -> 25 | D13: =MAX(1,_xlfn.MAXIFS(Tree!$C:$C,Tree!$A:$A,B13&".*")) -> 4
A14: Social & Government Programs | B14: social | C14: =COUNTIF(Tree!$A:$A,B14)+COUNTIF(Tree!$A:$A,B14&".*") -> 36 | D14: =MAX(1,_xlfn.MAXIFS(Tree!$C:$C,Tree!$A:$A,B14&".*")) -> 3
A15: Reinsurance | B15: reinsurance | C15: =COUNTIF(Tree!$A:$A,B15)+COUNTIF(Tree!$A:$A,B15&".*") -> 20 | D15: =MAX(1,_xlfn.MAXIFS(Tree!$C:$C,Tree!$A:$A,B15&".*")) -> 4
A16: Alternative Risk Transfer (ART) | B16: art | C16: =COUNTIF(Tree!$A:$A,B16)+COUNTIF(Tree!$A:$A,B16&".*") -> 27 | D16: =MAX(1,_xlfn.MAXIFS(Tree!$C:$C,Tree!$A:$A,B16&".*")) -> 4
A17: Total | C17: =SUM(C4:C16) -> 551 | D17: =MAX(D4:D16) -> 5
A18: Check: rows in Tree sheet | C18: =COUNTA(Tree!$A:$A)-1 -> 551
A20: Level | C20: Nodes at level
A21: 1 | C21: =COUNTIF(Tree!$C:$C,A21) -> 13
A22: 2 | C22: =COUNTIF(Tree!$C:$C,A22) -> 87
A23: 3 | C23: =COUNTIF(Tree!$C:$C,A23) -> 295
A24: 4 | C24: =COUNTIF(Tree!$C:$C,A24) -> 146
A25: 5 | C25: =COUNTIF(Tree!$C:$C,A25) -> 10
A26: Total | C26: =SUM(C21:C25) -> 551
A28: By market
A29: Personal | C29: =COUNTIF(Tree!$H:$H,A29) -> 223
A30: Commercial | C30: =COUNTIF(Tree!$H:$H,A30) -> 270
A31: Both | C31: =COUNTIF(Tree!$H:$H,A31) -> 58
A33: Approach and sources
A34: Scope: US market only. Product names, forms and notes follow US usage (e.g. ISO homeowners HO-1 to HO-8 forms, ISO commercial forms, NCCI workers' comp, ACA/Medicare/Medicaid programs, USDA Risk Management Agency crop programs).
A35: Compiled from general industry knowledge of publicly documented US sources: ISO/Verisk standard policy forms, NAIC model laws and consumer guides, Insurance Information Institute (III) explainers, CMS/Medicare.gov, HealthCare.gov, FEMA/NFIP, USDA RMA, SSA, NCCI and IRS publications. Figures (limits, thresholds, dates) are as generally published at the time of writing and change over time; verify current values before relying on them.
A36: Terminology varies: insurers, states and agents often use different names for the same product (see the Also Known As column). Many products differ by state, because insurance is regulated mainly at the state level.
A37: The tree is a learning aid, not legal or buying advice. Some products fit more than one branch; each appears once in its most common home, and a few government programs are also listed under Social & Government Programs with a cross-reference.
A38: Counts in this sheet are live formulas over the Tree sheet, so they update if rows are added or removed.

Sheet README
A1: Insurance Taxonomy (US market)
A2: A tree of US insurance product types for people new to insurance: individuals, developers joining insurance projects, new underwriters and product owners. The same data is exported to data/insurance-taxonomy.csv for the app.
A4: Sheets
A5: Tree | B5: One row per node (product type or grouping), ordered depth-first so the tree reads top to bottom. This is the machine-readable source.
A6: Outline | B6: The same tree as an indented outline, one column per level. Use the +/- buttons or the 1-6 outline level buttons at the top left to collapse and expand branches.
A7: Summary | B7: Node counts per root category and per level (live formulas), plus notes on sources and approach.
A8: README | B8: This sheet.
A10: Columns in the Tree sheet
A11: ID | B11: Stable, unique, dot-separated identifier built from the parent's ID plus a short slug, e.g. life.permanent.universal.iul. Lowercase letters, digits and underscores only. Use it as the key in the app; do not rely on row numbers.
A12: Parent ID | B12: ID of the parent node. Blank for the 13 root categories. Every non-blank Parent ID exists as an ID in the sheet.
A13: Level | B13: Depth in the tree: 1 = root category, 2 = its children, and so on. Always equals the parent's level + 1.
A14: Name | B14: Display name. Indented visually by level in Excel (cell indent only; the value has no leading spaces).
A15: Also Known As | B15: Other names, abbreviations or brand/state names for the same thing, separated by semicolons. Blank if none.
A16: Plain-English Description | B16: One or two sentences in simple language.
A17: Example | B17: A concrete, real-life example of who buys it or what it pays for.
A18: Personal/Commercial/Both | B18: Whether it is bought mainly by individuals/families (Personal), businesses/organizations (Commercial) or both.
A19: US Notes | B19: US-specific details: state vs federal regulation, state variations, key laws, program names. Blank where not applicable.
A20: Full Path | B20: Names from the root down to this node, separated by ' > '. Always equals the parent's Full Path + ' > ' + Name.
A22: How the tree is linked
A23: Parent/child | B23: Each row points to its parent through Parent ID. To build the tree: create a node for each row keyed by ID, then attach each node to the node whose ID equals its Parent ID. Rows with a blank Parent ID are roots.
A24: ID prefixes | B24: Because IDs are built from the parent's ID, every descendant's ID starts with its ancestor's ID followed by a dot. For example, all Life nodes start with 'life.'; all universal life types start with 'life.permanent.universal.'.
A25: Ordering | B25: Rows are in depth-first (pre-order) order: a parent always appears before its children, and siblings appear in a teaching-friendly order.
A26: Validation | B26: The file was checked by script: IDs are unique, every Parent ID exists, Level = parent Level + 1, and Full Path = parent Full Path + ' > ' + Name.
A28: Caveat | B28: Educational reference only; not legal, tax or buying advice. Details vary by state and change over time.
